<?xml version="1.0"?>
<robot name="myfirst">

  <material name="white">
    <color rgba="1 1 1 1"/>
  </material>

<material name="blue">
    <color rgba="0 0 0.8 1"/>
  </material>

 <link name="base_link">
    <visual>
 <origin rpy="0 0 0" xyz="0 0 0"/>
          <geometry>
         <mesh filename="package://urdf_tutorial/meshes/joint_6_5.stl"/>
	</geometry>
      <material name="white"/>
    </visual>
  </link>

 <link name="servo_2">
    <visual>
      <geometry>
        <box size="0.78 0.66 0.43"/>
      </geometry>
      <origin rpy="0 0 0" xyz="-0.14 0 0.355"/>
      <material name="blue"/>
    </visual>
  </link>

 <link name="servo_3">
    <visual>
      <geometry>
        <box size="0.62 0.34 0.47"/>
      </geometry>
      <origin rpy="0 0 0" xyz="0.16 0 0.663"/>
      <material name="white"/>
    </visual>
  </link>

 <link name="arm_1">
    <visual>
      <geometry>
        <box size="0.25 0.1 2.2"/>
      </geometry>
      <origin rpy="0 0 0" xyz="0 0.25 1.1"/>
      <material name="white"/>
    </visual>
  </link>

 <link name="servo_4">
    <visual>
      <geometry>
        <box size="0.34 0.47 0.62"/>
      </geometry>
      <origin rpy="0 0 0" xyz="0.045 -0.035 0"/>
      <material name="white"/>
    </visual>
  </link>

 <link name="arm_2">
    <visual>
      <geometry>
        <box size="0.15 0.05 1.5"/>
      </geometry>
      <origin rpy="0 0 0" xyz="-0.245 -0.025 0.75"/>
      <material name="white"/>
    </visual>
  </link>

 <link name="servo_5">
    <visual>
      <geometry>
        <box size="0.465 0.285 0.34"/>
      </geometry>
      <origin rpy="0 0 0" xyz="0.1575 0.1425 -0.17"/>
      <material name="white"/>
    </visual>
  </link>

 <link name="servo_6">
    <visual>
      <geometry>
        <box size="0.285 0.34 0.465"/>
      </geometry>
      <origin rpy="0 0 0" xyz="0 0 0.2875"/>
      <material name="white"/>
    </visual>
  </link>

 <link name="servo_7">
    <visual>
      <geometry>
        <box size="0.40 0.28 0.39"/>
      </geometry>
      <origin rpy="0 0 0" xyz="0.0375 0 0.425"/>
      <material name="white"/>
    </visual>
  </link>


  <joint name="joint_1" type="revolute">
    <axis rpy="0 0 0" xyz="0 0 1"/>
    <limit effort ="1000.0" lower="-3.14" upper="3.14" velocity="0.5"/>
    <parent link="base_link"/>
    <child link="servo_2"/>
    <origin rpy="0 0 0" xyz="-0.16 0 0.513"/>
  </joint>

  <joint name="joint_2" type="revolute">
    <axis rpy="0 0 0" xyz="0 1 0"/>
    <limit effort ="1000.0" lower="-3.14" upper="3.14" velocity="0.5"/>
    <parent link="servo_2"/>
    <child link="servo_3"/>
    <origin rpy="0 0 0" xyz="-0.315 0 0.355"/>
  </joint>

 <joint name="joint_2_arm_1" type="revolute">
    <axis rpy="0 0 0" xyz="0 0 1"/>
    <limit effort ="1000.0" lower="-3.14" upper="3.14" velocity="0.5"/>
    <parent link="servo_3"/>
    <child link="arm_1"/>
    <origin rpy="0 0 3.14" xyz="0 0 1.008"/>
  </joint>

  <joint name="arm_1_servo_4" type="fixed">
    <axis rpy="0 0 0" xyz="0 1 0"/>
    <limit effort ="1000.0" lower="-3.14" upper="3.14" velocity="0.5"/>
    <parent link="arm_1"/>
    <child link="servo_4"/>
    <origin rpy="0 0 0" xyz="0 0 2.2"/>
  </joint>


<joint name="servo_4_arm_2" type="revolute">
    <axis rpy="0 0 0" xyz="0 1 0"/>
    <limit effort ="1000.0" lower="-3.14" upper="3.14" velocity="0.5"/>
    <parent link="servo_4"/>
    <child link="arm_2"/>
    <origin rpy="0 0 0" xyz="0.045 -0.313 0.16"/>
  </joint>

  <joint name="arm_2_servo_5" type="fixed">
    <axis rpy="0 0 0" xyz="0 1 0"/>
    <limit effort ="1000.0" lower="-3.14" upper="3.14" velocity="0.5"/>
    <parent link="arm_2"/>
    <child link="servo_5"/>
    <origin rpy="0 0 0" xyz="-0.245 0 1.5"/>
  </joint>

<joint name="servo_5_servo_6" type="revolute">
    <axis rpy="0 0 0" xyz="0 0 1"/>
    <limit effort ="1000.0" lower="-3.14" upper="3.14" velocity="0.5"/>
    <parent link="servo_5"/>
    <child link="servo_6"/>
    <origin rpy="0 0 0" xyz="0.045 0.1425 -0.0325"/>
  </joint>

<joint name="servo_6_servo_7" type="revolute">
    <axis rpy="0 0 0" xyz="0 1 0"/>
    <limit effort ="1000.0" lower="-3.14" upper="3.14" velocity="0.5"/>
    <parent link="servo_6"/>
    <child link="servo_7"/>
    <origin rpy="0 0 0" xyz="0.045 0.1425 0.41"/>
  </joint>



</robot>
