<?xml version="1.0"?>
<robot name="myfirst">

  <material name="white">
    <color rgba="1 1 1 1"/>
  </material>

<material name="blue">
    <color rgba="0 0 0.8 1"/>
  </material>

 <link name="base_link">
    <visual>
 <origin rpy="0 0 0" xyz="0 0 0"/>
          <geometry>
 <box size="0.050 0.05 0.05"/>
	</geometry>
      <material name="white"/>
    </visual>
  </link>



 <link name="servo_1">
    <visual>
      <geometry>
         <mesh filename="file:///home/robot/catkin_ws/src/urdf_tutorial/meshes/joint_2_1.dae"/>
      </geometry>
      <origin rpy="0 0 0" xyz="0 0 0"/>
      <material name="blue"/>
    </visual>
  </link>

 <link name="servo_2">
    <visual>
      <geometry>
         <mesh filename="file:///home/robot/catkin_ws/src/urdf_tutorial/meshes/joint_3_2.dae"/>
      </geometry>
      <origin rpy="0 0 0" xyz="0 0 0"/>
      <material name="blue"/>
    </visual>
  </link>

 <link name="servo_3">
    <visual>
      <geometry>
         <mesh filename="file:///home/robot/catkin_ws/src/urdf_tutorial/meshes/joint_4_3.dae"/>
      </geometry>
      <origin rpy="0 0 0" xyz="0 0 0"/>
      <material name="blue"/>
    </visual>
  </link>

 <link name="servo_4">
    <visual>
      <geometry>
         <mesh filename="file:///home/robot/catkin_ws/src/urdf_tutorial/meshes/joint_5_4.dae"/>
      </geometry>
      <origin rpy="0 0 0" xyz="0 0 0"/>
      <material name="blue"/>
    </visual>
  </link>

 <link name="servo_5">
    <visual>
      <geometry>
         <mesh filename="file:///home/robot/catkin_ws/src/urdf_tutorial/meshes/joint_6_5.dae"/>
      </geometry>
      <origin rpy="0 0 0" xyz="0 0 0"/>
      <material name="blue"/>
    </visual>
  </link>

 <link name="servo_6">
    <visual>
      <geometry>
         <mesh filename="file:///home/robot/catkin_ws/src/urdf_tutorial/meshes/joint_7_6.dae"/>
      </geometry>
      <origin rpy="0 0 0" xyz="0 0 0"/>
      <material name="blue"/>
    </visual>
  </link>

 <link name="servo_7">
    <visual>
      <geometry>
         <mesh filename="file:///home/robot/catkin_ws/src/urdf_tutorial/meshes/hook.stl"/>
      </geometry>
      <origin rpy="0 0 0" xyz="0 0 0"/>
      <material name="blue"/>
    </visual>
  </link>

  <joint name="joint_1" type="revolute">
    <axis rpy="0 0 0" xyz="0 0 1"/>
    <limit effort ="1000.0" lower="-3.14" upper="3.14" velocity="0.5"/>
   <parent link="base_link"/>
    <child link="servo_1"/>
    <origin rpy="0 0 3.14" xyz="0 0 0.025"/>
  </joint>

  <joint name="joint_2" type="revolute">
    <axis rpy="0 0 0" xyz="0 1 0"/>
    <limit effort ="1000.0" lower="-3.14" upper="3.14" velocity="0.5"/>
    <parent link="servo_1"/>
    <child link="servo_2"/>
    <origin rpy="0 0 0" xyz="0.0435 0 0.0245"/>
  </joint>

  <joint name="joint_3" type="revolute">
    <axis rpy="0 0 0" xyz="1 0 0"/>
    <limit effort ="1000.0" lower="-3.14" upper="3.14" velocity="0.5"/>
    <parent link="servo_2"/>
    <child link="servo_3"/>
    <origin rpy="0 0 0" xyz="0.104 0.01675 0"/>
  </joint>

  <joint name="joint_4" type="revolute">
    <axis rpy="0 0 0" xyz="0 -1 0"/>
    <limit effort ="1000.0" lower="-3.14" upper="3.14" velocity="0.5"/>
    <parent link="servo_3"/>
    <child link="servo_4"/>
    <origin rpy="0 0 0" xyz="0.16911 -0.01413 -0.00487"/>
  </joint>

  <joint name="joint_5" type="revolute">
    <axis rpy="0 0 0" xyz="0 0 -1"/>
    <limit effort ="1000.0" lower="-3.14" upper="3.14" velocity="0.5"/>
    <parent link="servo_4"/>
    <child link="servo_5"/>
    <origin rpy="0 0 0" xyz="0.05118 -0.016 -0.0231"/>
  </joint>

  <joint name="joint_6" type="revolute">
    <axis rpy="0 0 0" xyz="1 0 0"/>
    <limit effort ="1000.0" lower="-3.14" upper="3.14" velocity="0.5"/>
    <parent link="servo_5"/>
    <child link="servo_6"/>
    <origin rpy="0 0 0" xyz="0.00156 0.00013 -0.21534"/>
  </joint>

  <joint name="joint_7" type="revolute">
    <axis rpy="0 0 0" xyz="0 0 -1"/>
    <limit effort ="1000.0" lower="-3.14" upper="3.14" velocity="0.5"/>
    <parent link="servo_6"/>
    <child link="servo_7"/>
    <origin rpy="0 0 0" xyz="-0.01153 0 -0.06009"/>
  </joint>






</robot>
