<?xml version="1.0" encoding="utf-8"?>
<!-- =================================================================================== -->
<!-- |    This document was autogenerated by xacro from feetech.urdf.xacro             | -->
<!-- |    EDITING THIS FILE BY HAND IS NOT RECOMMENDED                                 | -->
<!-- =================================================================================== -->
<robot name="feetech">
  <material name="blue">
    <color rgba="0 0 0.8 1"/>
  </material>
  <link name="base_link">
    <visual>
      <geometry>
        <box size="0.050 0.05 0.05"/>
      </geometry>
      <material name="blue"/>
    </visual>
    <collision>
      <geometry>
        <box size="0.050 0.05 0.05"/>
      </geometry>
    </collision>
  </link>
  <link name="head_base_link">
    <visual>
      <geometry>
        <mesh filename="file:///home/robot/catkin_ws/src/urdf_tutorial/meshes/headjoint_0.stl"/>
      </geometry>
    </visual>
    <collision>
      <geometry>
        <mesh filename="file:///home/robot/catkin_ws/src/urdf_tutorial/meshes/headjoint_0.stl"/>
      </geometry>
    </collision>
  </link>
  <joint name="headjoint_base" type="fixed">
    <parent link="base_link"/>
    <child link="head_base_link"/>
    <origin rpy="0 0 0" xyz="0 0 0.354"/>
  </joint>
  <link name="servo_0">
    <visual>
      <geometry>
        <mesh filename="file:///home/robot/catkin_ws/src/urdf_tutorial/meshes/joint_1_0.stl"/>
      </geometry>
    </visual>
    <collision>
      <geometry>
        <mesh filename="file:///home/robot/catkin_ws/src/urdf_tutorial/meshes/joint_1_0.stl"/>
      </geometry>
    </collision>
  </link>
  <joint name="joint_0" type="revolute">
    <safety_controller k_position="100.0" k_velocity="40.0" soft_lower_limit="-3.14" soft_upper_limit="3.14"/>
    <axis xyz="0 0 -1"/>
    <parent link="base_link"/>
    <child link="servo_0"/>
    <origin rpy="0 0 3.14" xyz="0 0 0"/>
    <limit effort="100" lower="-3.14" upper="3.14" velocity="1"/>
  </joint>
  <link name="servo_1">
    <visual>
      <geometry>
        <mesh filename="file:///home/robot/catkin_ws/src/urdf_tutorial/meshes/joint_2_1.stl"/>
      </geometry>
    </visual>
    <collision>
      <geometry>
        <mesh filename="file:///home/robot/catkin_ws/src/urdf_tutorial/meshes/joint_2_1.stl"/>
      </geometry>
    </collision>
  </link>
  <joint name="joint_1" type="revolute">
    <safety_controller k_position="100.0" k_velocity="40.0" soft_lower_limit="-1.25" soft_upper_limit="1.25"/>
    <axis xyz="0 0 1"/>
    <parent link="servo_0"/>
    <child link="servo_1"/>
    <origin rpy="0 0 0" xyz="0.10035 0 0.1002"/>
    <limit effort="100" lower="-1.57" upper="1.57" velocity="1"/>
  </joint>
  <link name="servo_2">
    <visual>
      <geometry>
        <mesh filename="file:///home/robot/catkin_ws/src/urdf_tutorial/meshes/joint_3_2.stl"/>
      </geometry>
      <material name="blue"/>
    </visual>
    <collision>
      <geometry>
        <mesh filename="file:///home/robot/catkin_ws/src/urdf_tutorial/meshes/joint_3_2.stl"/>
      </geometry>
    </collision>
  </link>
  <joint name="joint_2" type="revolute">
    <safety_controller k_position="100.0" k_velocity="40.0" soft_lower_limit="-1.3" soft_upper_limit="1.57"/>
    <axis xyz="0 -1 0"/>
    <parent link="servo_1"/>
    <child link="servo_2"/>
    <origin rpy="0 0 0" xyz="0.056 0 0.0325"/>
    <limit effort="100" lower="-1.35" upper="1.6" velocity="1"/>
  </joint>
  <link name="servo_3">
    <visual>
      <geometry>
        <mesh filename="file:///home/robot/catkin_ws/src/urdf_tutorial/meshes/joint_4_3.stl"/>
      </geometry>
    </visual>
    <collision>
      <geometry>
        <mesh filename="file:///home/robot/catkin_ws/src/urdf_tutorial/meshes/joint_4_3.stl"/>
      </geometry>
    </collision>
  </link>
  <joint name="joint_3" type="revolute">
    <safety_controller k_position="100.0" k_velocity="40.0" soft_lower_limit="-1.57" soft_upper_limit="1.57"/>
    <axis xyz="1 0 0"/>
    <parent link="servo_2"/>
    <child link="servo_3"/>
    <origin rpy="0 0 0" xyz="0.1155 0.0175 0"/>
    <limit effort="100" lower="-1.6" upper="1.6" velocity="3"/>
  </joint>
  <link name="servo_4">
    <visual>
      <geometry>
        <mesh filename="file:///home/robot/catkin_ws/src/urdf_tutorial/meshes/joint_5_4.stl"/>
      </geometry>
      <material name="blue"/>
    </visual>
    <collision>
      <geometry>
        <mesh filename="file:///home/robot/catkin_ws/src/urdf_tutorial/meshes/joint_5_4.stl"/>
      </geometry>
    </collision>
  </link>
  <joint name="joint_4" type="revolute">
    <safety_controller k_position="100.0" k_velocity="40.0" soft_lower_limit="-1.57" soft_upper_limit="1.57"/>
    <axis xyz="0 -1 0"/>
    <parent link="servo_3"/>
    <child link="servo_4"/>
    <origin rpy="0 0 0" xyz="0.16911 -0.01413 -0.00487"/>
    <limit effort="100" lower="-1.6" upper="1.6" velocity="3"/>
  </joint>
  <link name="servo_5">
    <visual>
      <geometry>
        <mesh filename="file:///home/robot/catkin_ws/src/urdf_tutorial/meshes/joint_6_5.stl"/>
      </geometry>
    </visual>
    <collision>
      <geometry>
        <mesh filename="file:///home/robot/catkin_ws/src/urdf_tutorial/meshes/joint_6_5.stl"/>
      </geometry>
    </collision>
  </link>
  <joint name="joint_5" type="revolute">
    <safety_controller k_position="100.0" k_velocity="40.0" soft_lower_limit="-1.57" soft_upper_limit="1.57"/>
    <axis xyz="0 0 -1"/>
    <parent link="servo_4"/>
    <child link="servo_5"/>
    <origin rpy="0 0 -1.57" xyz="0.05118 -0.016 -0.0231"/>
    <limit effort="100" lower="-1.6" upper="1.6" velocity="3"/>
  </joint>
  <link name="servo_6">
    <visual>
      <geometry>
        <mesh filename="file:///home/robot/catkin_ws/src/urdf_tutorial/meshes/joint_7_6.stl"/>
      </geometry>
      <material name="blue"/>
    </visual>
    <collision>
      <geometry>
        <mesh filename="file:///home/robot/catkin_ws/src/urdf_tutorial/meshes/joint_7_6.stl"/>
      </geometry>
    </collision>
  </link>
  <joint name="joint_6" type="revolute">
    <safety_controller k_position="100.0" k_velocity="40.0" soft_lower_limit="-1.57" soft_upper_limit="1.57"/>
    <axis xyz="1 0 0"/>
    <parent link="servo_5"/>
    <child link="servo_6"/>
    <origin rpy="0 0 0" xyz="0.00156 0.00013 -0.21534"/>
    <limit effort="100" lower="-1.6" upper="1.6" velocity="3"/>
  </joint>
  <link name="servo_7">
    <visual>
      <geometry>
        <mesh filename="file:///home/robot/catkin_ws/src/urdf_tutorial/meshes/hook.stl"/>
      </geometry>
    </visual>
    <collision>
      <geometry>
        <mesh filename="file:///home/robot/catkin_ws/src/urdf_tutorial/meshes/hook.stl"/>
      </geometry>
    </collision>
  </link>
  <joint name="joint_7" type="revolute">
    <safety_controller k_position="100.0" k_velocity="40.0" soft_lower_limit="-3.1" soft_upper_limit="3.1"/>
    <axis xyz="0 0 -1"/>
    <parent link="servo_6"/>
    <child link="servo_7"/>
    <origin rpy="0 0 0" xyz="-0.01153 0 -0.06009"/>
    <limit effort="100" lower="-3.14" upper="3.14" velocity="3"/>
  </joint>
  <link name="servo_8">
    <visual>
      <geometry>
        <mesh filename="file:///home/robot/catkin_ws/src/urdf_tutorial/meshes/headjoint_1_0.stl"/>
      </geometry>
    </visual>
    <collision>
      <geometry>
        <mesh filename="file:///home/robot/catkin_ws/src/urdf_tutorial/meshes/headjoint_1_0.stl"/>
      </geometry>
    </collision>
  </link>
  <joint name="headjoint_8" type="revolute">
    <safety_controller k_position="100.0" k_velocity="40.0" soft_lower_limit="-3.1" soft_upper_limit="3.1"/>
    <axis xyz="0 0 1"/>
    <parent link="head_base_link"/>
    <child link="servo_8"/>
    <origin rpy="0 0 0" xyz="0 0 0.0555"/>
    <limit effort="100" lower="-3.14" upper="3.14" velocity="10"/>
  </joint>
  <link name="servo_9">
    <visual>
      <geometry>
        <mesh filename="file:///home/robot/catkin_ws/src/urdf_tutorial/meshes/headjoint_2_1.stl"/>
      </geometry>
    </visual>
    <collision>
      <geometry>
        <mesh filename="file:///home/robot/catkin_ws/src/urdf_tutorial/meshes/headjoint_2_1.stl"/>
      </geometry>
    </collision>
  </link>
  <joint name="headjoint_9" type="revolute">
    <safety_controller k_position="100.0" k_velocity="40.0" soft_lower_limit="-0.35" soft_upper_limit="0.35"/>
    <axis xyz="0 -1 0"/>
    <parent link="servo_8"/>
    <child link="servo_9"/>
    <origin rpy="0 0 0" xyz="0 0 0.0425"/>
    <limit effort="100" lower="-0.40" upper="0.4" velocity="1"/>
  </joint>
  <material name="aluminum">
    <color rgba="0.5 0.5 0.5 1"/>
  </material>
  <material name="plastic">
    <color rgba="0.1 0.1 0.1 1"/>
  </material>
  <link name="realsense_link"/>
  <!-- camera body, with origin at bottom screw mount -->
  <joint name="camera_joint" type="fixed">
    <origin rpy="0 0 0" xyz="0 0 0"/>
    <parent link="realsense_link"/>
    <child link="camera_bottom_screw_frame"/>
  </joint>
  <link name="camera_bottom_screw_frame"/>
  <joint name="camera_link_joint" type="fixed">
    <origin rpy="0 0 0" xyz="0.0106 0.0175 0.0125"/>
    <parent link="camera_bottom_screw_frame"/>
    <child link="camera_link"/>
  </joint>
  <link name="camera_link">
    <visual>
      <!-- the mesh origin is at front plate in between the two infrared camera axes -->
      <origin rpy="1.57079632679 0 1.57079632679" xyz="0.0043 -0.0175 0"/>
      <geometry>
        <!-- <box size="${d435_cam_width} ${d435_cam_height} ${d435_cam_depth}"/> -->
        <mesh filename="package://realsense2_description/meshes/d435.dae"/>
      </geometry>
    </visual>
    <collision>
      <origin rpy="0 0 0" xyz="0 -0.0175 0"/>
      <geometry>
        <box size="0.02505 0.09 0.025"/>
      </geometry>
    </collision>
    <inertial>
      <!-- The following are not reliable values, and should not be used for modeling -->
      <mass value="0.072"/>
      <origin xyz="0 0 0"/>
      <inertia ixx="0.003881243" ixy="0.0" ixz="0.0" iyy="0.000498940" iyz="0.0" izz="0.003879257"/>
    </inertial>
  </link>
  <joint name="joint_realsense" type="fixed">
    <parent link="servo_9"/>
    <child link="realsense_link"/>
    <origin rpy="0 0 0" xyz="0.06527 0 0.015"/>
  </joint>
</robot>
