<?xml version="1.0"?>
<robot name="feetech" xmlns:xacro="http://www.ros.org/wiki/xacro">


  <material name="blue">
    <color rgba="0 0 0.8 1"/>
  </material>

    <link name="base_link">
      <visual>
        <geometry>
<box size="0.050 0.05 0.05"/>
        </geometry>
<material name="blue"/>
      </visual>
      <collision>
        <geometry>
<box size="0.050 0.05 0.05"/>
        </geometry>
      </collision>
    </link>


<xacro:property name="arm_id" value="servo" />
<xacro:property name="description_pkg" value="file:///home/robot/catkin_ws/src/urdf_tutorial" />

<link name="head_base_link">
      <visual>
        <geometry>
          <mesh filename="${description_pkg}/meshes/headjoint_0.stl"/>
        </geometry>
      </visual>
      <collision>
        <geometry>
          <mesh filename="${description_pkg}/meshes/headjoint_0.stl"/>
        </geometry>
      </collision>
    </link>

<joint name="headjoint_base" type="fixed">
        
<parent link="base_link"/>
    <child link="head_base_link"/>
    <origin rpy="0 0 0" xyz="0 0 0.354"/>
 </joint>


 <link name="${arm_id}_0">
      <visual>
        <geometry>
          <mesh filename="${description_pkg}/meshes/joint_1_0.stl"/>
        </geometry>
      </visual>
      <collision>
        <geometry>
          <mesh filename="${description_pkg}/meshes/joint_1_0.stl"/>
        </geometry>
      </collision>
    </link>

    <joint name="joint_0" type="revolute">
      <safety_controller k_position="100.0" k_velocity="40.0" soft_lower_limit="-3.14" soft_upper_limit="3.14"/>
<axis xyz="0 0 -1"/>  
<parent link="base_link"/>
    <child link="${arm_id}_0"/>
    <origin rpy="0 0 3.14" xyz="0 0 0"/>
      <limit effort="100" lower="-3.14" upper="3.14" velocity="1"/>
    </joint>


 <link name="${arm_id}_1">
      <visual>
        <geometry>
          <mesh filename="${description_pkg}/meshes/joint_2_1.stl"/>
        </geometry>
      </visual>
      <collision>
        <geometry>
          <mesh filename="${description_pkg}/meshes/joint_2_1.stl"/>
        </geometry>
      </collision>
    </link>

    <joint name="joint_1" type="revolute">
      <safety_controller k_position="100.0" k_velocity="40.0" soft_lower_limit="-1.047" soft_upper_limit="1.047"/>
<axis xyz="0 0 1"/>  
<parent link="${arm_id}_0"/>
    <child link="${arm_id}_1"/>
    <origin rpy="0 0 0" xyz="0.10035 0 0.1002"/>
      <limit effort="100" lower="-1.57" upper="1.57" velocity="1"/>
    </joint>



    <link name="${arm_id}_2">
      <visual>
        <geometry>
          <mesh filename="${description_pkg}/meshes/joint_3_2.stl"/>
        </geometry>
<material name="blue"/>
      </visual>
      <collision>
        <geometry>
          <mesh filename="${description_pkg}/meshes/joint_3_2.stl"/>
        </geometry>
      </collision>
    </link>

    <joint name="joint_2" type="revolute">
      <safety_controller k_position="100.0" k_velocity="40.0" soft_lower_limit="-1.3" soft_upper_limit="1.9"/>
      <axis xyz="0 -1 0"/>    
<parent link="${arm_id}_1"/>
    <child link="${arm_id}_2"/>
    <origin rpy="0 0 0" xyz="0.056 0 0.0325"/>

      <limit effort="100" lower="-1.35" upper="1.57" velocity="1"/>
    </joint>

    <link name="${arm_id}_3">
      <visual>
        <geometry>
          <mesh filename="${description_pkg}/meshes/joint_4_3.stl"/>
        </geometry>
      </visual>
      <collision>
        <geometry>
          <mesh filename="${description_pkg}/meshes/joint_4_3.stl"/>
        </geometry>
      </collision>
    </link>

    <joint name="joint_3" type="revolute">
      <safety_controller k_position="100.0" k_velocity="40.0" soft_lower_limit="-3.14" soft_upper_limit="3.14"/>
         <axis xyz="1 0 0"/>
<parent link="${arm_id}_2"/>
    <child link="${arm_id}_3"/>
    <origin rpy="0 0 0" xyz="0.1155 0.0175 0"/>

      <limit effort="100" lower="-1.57" upper="1.57" velocity="3"/>
    </joint>

    <link name="${arm_id}_4">
      <visual>
        <geometry>
          <mesh filename="${description_pkg}/meshes/joint_5_4.stl"/>
        </geometry>
<material name="blue"/>
      </visual>
      <collision>
        <geometry>
          <mesh filename="${description_pkg}/meshes/joint_5_4.stl"/>
        </geometry>
      </collision>
    </link>

    <joint name="joint_4" type="revolute">
      <safety_controller k_position="100.0" k_velocity="40.0" soft_lower_limit="-1.55" soft_upper_limit="1.55"/>
         <axis xyz="0 -1 0"/>
<parent link="${arm_id}_3"/>
    <child link="${arm_id}_4"/>
    <origin rpy="0 0 0" xyz="0.16911 -0.01413 -0.00487"/>
      <limit effort="100" lower="-1.57" upper="1.57" velocity="3"/>
    </joint>

    <link name="${arm_id}_5">
      <visual>
        <geometry>
          <mesh filename="${description_pkg}/meshes/joint_6_5.stl"/>
        </geometry>
      </visual>
      <collision>
        <geometry>
          <mesh filename="${description_pkg}/meshes/joint_6_5.stl"/>
        </geometry>
      </collision>
    </link>

    <joint name="joint_5" type="revolute">
      <safety_controller k_position="100.0" k_velocity="40.0" soft_lower_limit="-3.14" soft_upper_limit="3.14"/>
        <axis xyz="0 0 -1"/>
 <parent link="${arm_id}_4"/>
    <child link="${arm_id}_5"/>
        <origin rpy="0 0 -1.57" xyz="0.05118 -0.016 -0.0231"/>
      <limit effort="100" lower="-2" upper="2" velocity="3"/>
    </joint>


    <link name="${arm_id}_6">
      <visual>
        <geometry>
          <mesh filename="${description_pkg}/meshes/joint_7_6.stl"/>
        </geometry>
<material name="blue"/>
      </visual>
      <collision>
        <geometry>
          <mesh filename="${description_pkg}/meshes/joint_7_6.stl"/>
        </geometry>
      </collision>
    </link>

    <joint name="joint_6" type="revolute">
      <safety_controller k_position="100.0" k_velocity="40.0" soft_lower_limit="-1.5" soft_upper_limit="1.5"/>
        <axis xyz="1 0 0"/>
	<parent link="${arm_id}_5"/>
    <child link="${arm_id}_6"/>
    <origin rpy="0 0 0" xyz="0.00156 0.00013 -0.21534"/>
      <limit effort="100" lower="-1.57" upper="1.57" velocity="3"/>
    </joint>


    <link name="${arm_id}_7">
      <visual>
        <geometry>
          <mesh filename="${description_pkg}/meshes/hook.stl"/>
        </geometry>
      </visual>
      <collision>
        <geometry>
          <mesh filename="${description_pkg}/meshes/hook.stl"/>
        </geometry>
      </collision>
    </link>

    <joint name="joint_7" type="revolute">
      <safety_controller k_position="100.0" k_velocity="40.0" soft_lower_limit="-3.1" soft_upper_limit="3.1"/>
       <axis xyz="0 0 -1"/>
<parent link="${arm_id}_6"/>
    <child link="${arm_id}_7"/>
    <origin rpy="0 0 0" xyz="-0.01153 0 -0.06009"/>
      <limit effort="100" lower="-3.14" upper="3.14" velocity="3"/>
    </joint>


    <link name="${arm_id}_8">
      <visual>
        <geometry>
          <mesh filename="${description_pkg}/meshes/headjoint_1_0.stl"/>
        </geometry>
      </visual>
      <collision>
        <geometry>
          <mesh filename="${description_pkg}/meshes/headjoint_1_0.stl"/>
        </geometry>
      </collision>
    </link>

    <joint name="headjoint_8" type="revolute">
      <safety_controller k_position="100.0" k_velocity="40.0" soft_lower_limit="-3.1" soft_upper_limit="3.1"/>
       <axis xyz="0 0 1"/>
<parent link="head_base_link"/>
    <child link="${arm_id}_8"/>
    <origin rpy="0 0 0" xyz="0 0 0.0555"/>
      <limit effort="100" lower="-3.14" upper="3.14" velocity="3"/>
    </joint>

    <link name="${arm_id}_9">
      <visual>
        <geometry>
          <mesh filename="${description_pkg}/meshes/headjoint_2_1.stl"/>
        </geometry>
      </visual>
      <collision>
        <geometry>
          <mesh filename="${description_pkg}/meshes/headjoint_2_1.stl"/>
        </geometry>
      </collision>
    </link>

    <joint name="headjoint_9" type="revolute">
      <safety_controller k_position="100.0" k_velocity="40.0" soft_lower_limit="-0.35" soft_upper_limit="0.35"/>
       <axis xyz="0 -1 0"/>
<parent link="${arm_id}_8"/>
    <child link="${arm_id}_9"/>
    <origin rpy="0 0 0" xyz="0 0 0.0425"/>
      <limit effort="100" lower="-0.40" upper="0.4" velocity="3"/>
    </joint>


</robot>
