<?xml version="1.0"?>
<robot name="myfirst" xmlns:xacro="http://www.ros.org/wiki/xacro">

  <material name="blue">
    <color rgba="0 0 0.8 1"/>
  </material>

    <link name="base_link">
      <visual>
        <geometry>
<box size="0.050 0.05 0.05"/>
        </geometry>
<material name="blue"/>
      </visual>
      <collision>
        <geometry>
<box size="0.050 0.05 0.05"/>
        </geometry>
      </collision>
    </link>

<link name="servo_0">
      <visual>
        <geometry>
          <mesh filename="${description_pkg}/meshes/joint_1_0.stl"/>
        </geometry>
      </visual>
      <collision>
        <geometry>
          <mesh filename="${description_pkg}/meshes/joint_1_0.stl"/>
        </geometry>
      </collision>
    </link>

    <joint name="joint_0" type="revolute">
      <safety_controller k_position="100.0" k_velocity="40.0" soft_lower_limit="-1.3" soft_upper_limit="1.3"/>
<axis xyz="0 0 1"/>  
<parent link="base_link"/>
    <child link="servo_0"/>
    <origin rpy="0 0 3.14" xyz="0 0 0"/>
      <limit effort="87" lower="-1.325" upper="1.325" velocity="2.1750"/>
    </joint>

 <link name="servo_1">
      <visual>
        <geometry>
          <mesh filename="${description_pkg}/meshes/joint_2_1.stl"/>
        </geometry>
      </visual>
      <collision>
        <geometry>
          <mesh filename="${description_pkg}/meshes/joint_2_1.stl"/>
        </geometry>
      </collision>
    </link>

    <joint name="joint_1" type="revolute">
      <safety_controller k_position="100.0" k_velocity="40.0" soft_lower_limit="-1.3" soft_upper_limit="1.3"/>
<axis xyz="0 0 1"/>  
<parent link="servo_0"/>
    <child link="servo_1"/>
    <origin rpy="0 0 3.14" xyz="0.10035 0 0.1002"/>
      <limit effort="87" lower="-1.325" upper="1.325" velocity="2.1750"/>
    </joint>

    <link name="servo_2">
      <visual>
        <geometry>
          <mesh filename="${description_pkg}/meshes/joint_3_2.stl"/>
        </geometry>
      </visual>
      <collision>
        <geometry>
          <mesh filename="${description_pkg}/meshes/joint_3_2.stl"/>
        </geometry>
      </collision>
    </link>

    <joint name="joint_2" type="revolute">
      <safety_controller k_position="100.0" k_velocity="40.0" soft_lower_limit="-1.3" soft_upper_limit="1.9"/>
      <axis xyz="0 -1 0"/>    
<parent link="servo_1"/>
    <child link="servo_2"/>
    <origin rpy="0 0 0" xyz="0.056 0 0.0325"/>

      <limit effort="87" lower="-1.35" upper="1.93" velocity="2.1750"/>
    </joint>

    <link name="servo_3">
      <visual>
        <geometry>
          <mesh filename="${description_pkg}/meshes/joint_4_3.stl"/>
        </geometry>
      </visual>
      <collision>
        <geometry>
          <mesh filename="${description_pkg}/meshes/joint_4_3.stl"/>
        </geometry>
      </collision>
    </link>

    <joint name="joint_3" type="revolute">
      <safety_controller k_position="100.0" k_velocity="40.0" soft_lower_limit="-3.14" soft_upper_limit="3.14"/>
         <axis xyz="1 0 0"/>
<parent link="servo_2"/>
    <child link="servo_3"/>
    <origin rpy="0 0 0" xyz="0.1155 0.0175 0"/>

      <limit effort="87" lower="-3.14" upper="3.14" velocity="2.1750"/>
    </joint>


    <link name="servo_4">
      <visual>
        <geometry>
          <mesh filename="${description_pkg}/meshes/joint_5_4.stl"/>
        </geometry>
      </visual>
      <collision>
        <geometry>
          <mesh filename="${description_pkg}/meshes/joint_5_4.stl"/>
        </geometry>
      </collision>
    </link>

    <joint name="joint_4" type="revolute">
      <safety_controller k_position="100.0" k_velocity="40.0" soft_lower_limit="-1.55" soft_upper_limit="1.55"/>
         <axis xyz="0 -1 0"/>
<parent link="servo_3"/>
    <child link="servo_4"/>
    <origin rpy="0 0 0" xyz="0.16911 -0.01413 -0.00487"/>
      <limit effort="87" lower="-1.56" upper="1.58" velocity="2.1750"/>
    </joint>

    <link name="servo_5">
      <visual>
        <geometry>
          <mesh filename="${description_pkg}/meshes/joint_6_5.stl"/>
        </geometry>
      </visual>
      <collision>
        <geometry>
          <mesh filename="${description_pkg}/meshes/joint_6_5.stl"/>
        </geometry>
      </collision>
    </link>

    <joint name="joint_5" type="revolute">
      <safety_controller k_position="100.0" k_velocity="40.0" soft_lower_limit="-3.14" soft_upper_limit="3.14"/>
        <axis xyz="0 0 -1"/>
 <parent link="servo_4"/>
    <child link="servo_5"/>
        <origin rpy="0 0 0" xyz="0.05118 -0.016 -0.0231"/>
      <limit effort="87" lower="-3.14" upper="3.14" velocity="2.1750"/>
    </joint>


    <link name="servo_6">
      <visual>
        <geometry>
          <mesh filename="${description_pkg}/meshes/joint_7_6.stl"/>
        </geometry>
      </visual>
      <collision>
        <geometry>
          <mesh filename="${description_pkg}/meshes/joint_7_6.stl"/>
        </geometry>
      </collision>
    </link>

    <joint name="joint_6" type="revolute">
      <safety_controller k_position="100.0" k_velocity="40.0" soft_lower_limit="-1.5" soft_upper_limit="1.5"/>
        <axis xyz="1 0 0"/>
	<parent link="servo_5"/>
    <child link="servo_6"/>
    <origin rpy="0 0 0" xyz="0.00156 0.00013 -0.21534"/>
      <limit effort="87" lower="-1.53" upper="1.53" velocity="2.1750"/>
    </joint>


    <link name="servo_7">
      <visual>
        <geometry>
          <mesh filename="${description_pkg}/meshes/hook.stl"/>
        </geometry>
      </visual>
      <collision>
        <geometry>
          <mesh filename="${description_pkg}/meshes/hook.stl"/>
        </geometry>
      </collision>
    </link>

    <joint name="joint_7" type="revolute">
      <safety_controller k_position="100.0" k_velocity="40.0" soft_lower_limit="-3.14" soft_upper_limit="3.14"/>
       <axis xyz="0 0 -1"/>
<parent link="servo_6"/>
    <child link="servo_7"/>
    <origin rpy="0 0 0" xyz="-0.01153 0 -0.06009"/>
      <limit effort="87" lower="-3.14" upper="3.14" velocity="2.1750"/>
    </joint>

</robot>
